Workbook

Sheet Dataset
A1: CIF | B1: Customer Name | C1: Usia | D1: Jenis Kelamin | E1: SND | F1: Kode Transaksi | G1: Range Usia | H1: Region | I1: Balance | J1: Month | K1: No Telepon | L1: Flag | P1: Logic
A2: 1173603 | B2: Erna Susanto | C2: 30 | D2: Perempuan | E2: SND04 | F2: 521-17187 | G2: 25-35 | H2: Jawa Timur | I2: 7349830 | J2: 45658 | K2: 81134566 | L2: {=_xlfn.IFS(LEN(K2)<=9,"No Palsu",LEN(K2)<=12,"No Asli",LEN(K2)>12,"No Palsu")} -> No Palsu | P2: No Asli | Q2: 10-12
A3: 1204998 | B3: Indah Susanti | C3: 25 | D3: Perempuan | E3: SND12 | F3: 808-40420 | G3: 20-25 | H3: Sulawesi Tenggara | I3: 2819899 | J3: 45689 | K3: 82134527811 | L3: {=_xlfn.IFS(LEN(K3)<=9,"No Palsu",LEN(K3)<=12,"No Asli",LEN(K3)>12,"No Palsu")} -> No Asli | P3: No palsu | Q3: >12
A4: 1285551 | B4: Gilang Wibowo | C4: 49 | D4: Laki-laki | E4: SND12 | F4: 620-47433 | G4: 35-50 | H4: Sulawesi Tenggara | I4: 5489398 | J4: 45717 | K4: 811322674 | L4: {=_xlfn.IFS(LEN(K4)<=9,"No Palsu",LEN(K4)<=12,"No Asli",LEN(K4)>12,"No Palsu")} -> No Palsu | P4: No palsu | Q4: <=9
A5: 1299582 | B5: Putri Hidayat | C5: 26 | D5: Laki-laki | E5: SND05 | F5: 413-91280 | G5: 25-35 | H5: Kalimantan | I5: 6481487 | J5: 45748 | K5: 8582334567896 | L5: {=_xlfn.IFS(LEN(K5)<=9,"No Palsu",LEN(K5)<=12,"No Asli",LEN(K5)>12,"No Palsu")} -> No Palsu
A6: 1299582 | B6: Putri Hidayat | C6: 26 | D6: Laki-laki | E6: SND05 | F6: 413-91280 | G6: 25-35 | H6: Kalimantan | I6: 6481487 | J6: 45778 | K6: 8213456789 | L6: {=_xlfn.IFS(LEN(K6)<=9,"No Palsu",LEN(K6)<=12,"No Asli",LEN(K6)>12,"No Palsu")} -> No Asli
A7: 1336094 | B7: Intan Susanto | C7: 28 | D7: Laki-laki | E7: SND09 | F7: 521-60562 | G7: 25-35 | H7: Bali | I7: 9601023 | J7: 45809 | K7: 8221907561 | L7: {=_xlfn.IFS(LEN(K7)<=9,"No Palsu",LEN(K7)<=12,"No Asli",LEN(K7)>12,"No Palsu")} -> No Asli
A8: 1357884 | B8: patrio satrio | C8: 21 | D8: Laki-laki | E8: SND08 | F8: 712-55086 | G8: 20-25 | H8: Papua | I8: 7966406 | J8: 45839 | K8: 81134567888 | L8: {=_xlfn.IFS(LEN(K8)<=9,"No Palsu",LEN(K8)<=12,"No Asli",LEN(K8)>12,"No Palsu")} -> No Asli
A9: 1425629 | B9: Kartika Wijaya | C9: 57 | D9: Laki-laki | E9: SND12 | F9: 521-81560 | G9: >50 | H9: Sulawesi Tenggara | I9: 8348293 | J9: 45870 | K9: 8083421567892 | L9: {=_xlfn.IFS(LEN(K9)<=9,"No Palsu",LEN(K9)<=12,"No Asli",LEN(K9)>12,"No Palsu")} -> No Palsu
A10: 1523208 | B10: Nanda Sari | C10: 30 | D10: Laki-laki | E10: SND04 | F10: 621-48496 | G10: 25-35 | H10: Jawa Timur | I10: 1585762 | J10: 45901 | K10: 81134566 | L10: {=_xlfn.IFS(LEN(K10)<=9,"No Palsu",LEN(K10)<=12,"No Asli",LEN(K10)>12,"No Palsu")} -> No Palsu
A11: 1611608 | B11: Maya Putra | C11: 16 | D11: Laki-laki | E11: SND03 | F11: 413-17583 | G11: <20 | H11: Jawa Tengah | I11: 6918785 | J11: 45931 | K11: 82134527811 | L11: {=_xlfn.IFS(LEN(K11)<=9,"No Palsu",LEN(K11)<=12,"No Asli",LEN(K11)>12,"No Palsu")} -> No Asli
A12: 1650584 | B12: Erna Pratama | C12: 33 | D12: Perempuan | E12: SND08 | F12: 413-87958 | G12: 25-35 | H12: Papua | I12: 2361255 | J12: 45962 | K12: 811322674 | L12: {=_xlfn.IFS(LEN(K12)<=9,"No Palsu",LEN(K12)<=12,"No Asli",LEN(K12)>12,"No Palsu")} -> No Palsu
A13: 1662297 | B13: Lina Hidayat | C13: 23 | D13: Perempuan | E13: SND03 | F13: 620-36013 | G13: 20-25 | H13: Jawa Tengah | I13: 4486948 | J13: 45992 | K13: 8582334567896 | L13: {=_xlfn.IFS(LEN(K13)<=9,"No Palsu",LEN(K13)<=12,"No Asli",LEN(K13)>12,"No Palsu")} -> No Palsu
A14: 1813196 | B14: Indah Siregar | C14: 56 | D14: Perempuan | E14: SND03 | F14: 712-96198 | G14: >50 | H14: Jawa Tengah | I14: 5986742 | J14: 45658 | K14: 8213456789 | L14: {=_xlfn.IFS(LEN(K14)<=9,"No Palsu",LEN(K14)<=12,"No Asli",LEN(K14)>12,"No Palsu")} -> No Asli
A15: 1844086 | B15: Gilang Rahayu | C15: 53 | D15: Perempuan | E15: SND11 | F15: 620-70666 | G15: >50 | H15: Sulawesi Utara | I15: 6349125 | J15: 45689 | K15: 8221907561 | L15: {=_xlfn.IFS(LEN(K15)<=9,"No Palsu",LEN(K15)<=12,"No Asli",LEN(K15)>12,"No Palsu")} -> No Asli
A16: 1894133 | B16: Joko Hidayat | C16: 16 | D16: Laki-laki | E16: SND02 | F16: 712-75962 | G16: <20 | H16: Sumatera Selatan | I16: 3491453 | J16: 45717 | K16: 81134567888 | L16: {=_xlfn.IFS(LEN(K16)<=9,"No Palsu",LEN(K16)<=12,"No Asli",LEN(K16)>12,"No Palsu")} -> No Asli
... A174: 9389684 | B174: ari suteri | C174: 26 | D174: Laki-laki | E174: SND07 | F174: 413-57677 | G174: 25-35 | H174: DKI Jakarta | I174: 1366017 | J174: 45748 | K174: 8083421567892 | L174: {=_xlfn.IFS(LEN(K174)<=9,"No Palsu",LEN(K174)<=12,"No Asli",LEN(K174)>12,"No Palsu")} -> No Palsu

Sheet Output
C2: FUNDING PERFORMANCE
B4: I. Performa Funding Region Based On Total And Average Funding
C6: Region | D6: Total Balance | E6: Rata-Rata Balance
C7: Unmapping | D7: =SUMIF(Dataset!$H$2:$H$1048576,Output!C7,Dataset!$I$2:$I$1048576) -> 54096785 | E7: =AVERAGEIF(Dataset!$H$2:$H$1048576,Output!C7,Dataset!$I$2:$I$1048576) -> 6010753.9
C8: Sulawesi Tenggara | D8: =SUMIF(Dataset!$H$2:$H$1048576,Output!C8,Dataset!$I$2:$I$1048576) -> 71416001 | E8: =AVERAGEIF(Dataset!$H$2:$H$1048576,Output!C8,Dataset!$I$2:$I$1048576) -> 5951333.4
C9: DKI Jakarta | D9: =SUMIF(Dataset!$H$2:$H$1048576,Output!C9,Dataset!$I$2:$I$1048576) -> 55344572 | E9: =AVERAGEIF(Dataset!$H$2:$H$1048576,Output!C9,Dataset!$I$2:$I$1048576) -> 5534457.2
C10: Sulawesi Utara | D10: =SUMIF(Dataset!$H$2:$H$1048576,Output!C10,Dataset!$I$2:$I$1048576) -> 80073422 | E10: =AVERAGEIF(Dataset!$H$2:$H$1048576,Output!C10,Dataset!$I$2:$I$1048576) -> 5338228.1
C11: Kalimantan | D11: =SUMIF(Dataset!$H$2:$H$1048576,Output!C11,Dataset!$I$2:$I$1048576) -> 63649090 | E11: =AVERAGEIF(Dataset!$H$2:$H$1048576,Output!C11,Dataset!$I$2:$I$1048576) -> 5304090.8
C12: Jawa Tengah | D12: =SUMIF(Dataset!$H$2:$H$1048576,Output!C12,Dataset!$I$2:$I$1048576) -> 90116110 | E12: =AVERAGEIF(Dataset!$H$2:$H$1048576,Output!C12,Dataset!$I$2:$I$1048576) -> 5300947.6
C13: Sumatera Utara | D13: =SUMIF(Dataset!$H$2:$H$1048576,Output!C13,Dataset!$I$2:$I$1048576) -> 42021415 | E13: =AVERAGEIF(Dataset!$H$2:$H$1048576,Output!C13,Dataset!$I$2:$I$1048576) -> 5252676.9
C14: Bali | D14: =SUMIF(Dataset!$H$2:$H$1048576,Output!C14,Dataset!$I$2:$I$1048576) -> 87340863 | E14: =AVERAGEIF(Dataset!$H$2:$H$1048576,Output!C14,Dataset!$I$2:$I$1048576) -> 5137697.8
C15: Jawa Timur | D15: =SUMIF(Dataset!$H$2:$H$1048576,Output!C15,Dataset!$I$2:$I$1048576) -> 93870670 | E15: =AVERAGEIF(Dataset!$H$2:$H$1048576,Output!C15,Dataset!$I$2:$I$1048576) -> 4940561.6
C16: Sumatera Selatan | D16: =SUMIF(Dataset!$H$2:$H$1048576,Output!C16,Dataset!$I$2:$I$1048576) -> 67448255 | E16: =AVERAGEIF(Dataset!$H$2:$H$1048576,Output!C16,Dataset!$I$2:$I$1048576) -> 4817732.5
C17: Papua | D17: =SUMIF(Dataset!$H$2:$H$1048576,Output!C17,Dataset!$I$2:$I$1048576) -> 46577549 | E17: =AVERAGEIF(Dataset!$H$2:$H$1048576,Output!C17,Dataset!$I$2:$I$1048576) -> 4657754.9
C18: Jawa Barat | D18: =SUMIF(Dataset!$H$2:$H$1048576,Output!C18,Dataset!$I$2:$I$1048576) -> 76602460 | E18: =AVERAGEIF(Dataset!$H$2:$H$1048576,Output!C18,Dataset!$I$2:$I$1048576) -> 4506027.1
C19: Maluku | D19: =SUMIF(Dataset!$H$2:$H$1048576,Output!C19,Dataset!$I$2:$I$1048576) -> 50826050 | E19: =AVERAGEIF(Dataset!$H$2:$H$1048576,Output!C19,Dataset!$I$2:$I$1048576) -> 3909696.2
B21: II. Performa Funding By Gender For Each Reagion
C23: Region | D23: Balance by Gender | F23: Total Balance
D24: Male | E24: Female
C25: Unmapping | D25: =SUMIFS(Dataset!$I$2:$I$174,Dataset!$H$2:$H$174,Output!C25,Dataset!$D$2:$D$174,"Laki-laki") -> 23509134 | E25: =SUMIFS(Dataset!$I$2:$I$174,Dataset!$H$2:$H$174,Output!C25,Dataset!$D$2:$D$174,"Perempuan") -> 30587651 | F25: =D25+E25 -> 54096785
C26: Sulawesi Tenggara | D26: =SUMIFS(Dataset!$I$2:$I$174,Dataset!$H$2:$H$174,Output!C26,Dataset!$D$2:$D$174,"Laki-laki") -> 38889087 | E26: =SUMIFS(Dataset!$I$2:$I$174,Dataset!$H$2:$H$174,Output!C26,Dataset!$D$2:$D$174,"Perempuan") -> 32526914 | F26: =D26+E26 -> 71416001
C27: DKI Jakarta | D27: =SUMIFS(Dataset!$I$2:$I$174,Dataset!$H$2:$H$174,Output!C27,Dataset!$D$2:$D$174,"Laki-laki") -> 43733943 | E27: =SUMIFS(Dataset!$I$2:$I$174,Dataset!$H$2:$H$174,Output!C27,Dataset!$D$2:$D$174,"Perempuan") -> 11610629 | F27: =D27+E27 -> 55344572
C28: Sulawesi Utara | D28: =SUMIFS(Dataset!$I$2:$I$174,Dataset!$H$2:$H$174,Output!C28,Dataset!$D$2:$D$174,"Laki-laki") -> 46882279 | E28: =SUMIFS(Dataset!$I$2:$I$174,Dataset!$H$2:$H$174,Output!C28,Dataset!$D$2:$D$174,"Perempuan") -> 33191143 | F28: =D28+E28 -> 80073422
C29: Kalimantan | D29: =SUMIFS(Dataset!$I$2:$I$174,Dataset!$H$2:$H$174,Output!C29,Dataset!$D$2:$D$174,"Laki-laki") -> 26694161 | E29: =SUMIFS(Dataset!$I$2:$I$174,Dataset!$H$2:$H$174,Output!C29,Dataset!$D$2:$D$174,"Perempuan") -> 36954929 | F29: =D29+E29 -> 63649090
C30: Jawa Tengah | D30: =SUMIFS(Dataset!$I$2:$I$174,Dataset!$H$2:$H$174,Output!C30,Dataset!$D$2:$D$174,"Laki-laki") -> 32209403 | E30: =SUMIFS(Dataset!$I$2:$I$174,Dataset!$H$2:$H$174,Output!C30,Dataset!$D$2:$D$174,"Perempuan") -> 57906707 | F30: =D30+E30 -> 90116110
C31: Sumatera Utara | D31: =SUMIFS(Dataset!$I$2:$I$174,Dataset!$H$2:$H$174,Output!C31,Dataset!$D$2:$D$174,"Laki-laki") -> 6068646 | E31: =SUMIFS(Dataset!$I$2:$I$174,Dataset!$H$2:$H$174,Output!C31,Dataset!$D$2:$D$174,"Perempuan") -> 35952769 | F31: =D31+E31 -> 42021415
C32: Bali | D32: =SUMIFS(Dataset!$I$2:$I$174,Dataset!$H$2:$H$174,Output!C32,Dataset!$D$2:$D$174,"Laki-laki") -> 65245718 | E32: =SUMIFS(Dataset!$I$2:$I$174,Dataset!$H$2:$H$174,Output!C32,Dataset!$D$2:$D$174,"Perempuan") -> 22095145 | F32: =D32+E32 -> 87340863
C33: Jawa Timur | D33: =SUMIFS(Dataset!$I$2:$I$174,Dataset!$H$2:$H$174,Output!C33,Dataset!$D$2:$D$174,"Laki-laki") -> 53113216 | E33: =SUMIFS(Dataset!$I$2:$I$174,Dataset!$H$2:$H$174,Output!C33,Dataset!$D$2:$D$174,"Perempuan") -> 40757454 | F33: =D33+E33 -> 93870670
C34: Sumatera Selatan | D34: =SUMIFS(Dataset!$I$2:$I$174,Dataset!$H$2:$H$174,Output!C34,Dataset!$D$2:$D$174,"Laki-laki") -> 45059950 | E34: =SUMIFS(Dataset!$I$2:$I$174,Dataset!$H$2:$H$174,Output!C34,Dataset!$D$2:$D$174,"Perempuan") -> 22388305 | F34: =D34+E34 -> 67448255
C35: Papua | D35: =SUMIFS(Dataset!$I$2:$I$174,Dataset!$H$2:$H$174,Output!C35,Dataset!$D$2:$D$174,"Laki-laki") -> 28600099 | E35: =SUMIFS(Dataset!$I$2:$I$174,Dataset!$H$2:$H$174,Output!C35,Dataset!$D$2:$D$174,"Perempuan") -> 17977450 | F35: =D35+E35 -> 46577549
C36: Jawa Barat | D36: =SUMIFS(Dataset!$I$2:$I$174,Dataset!$H$2:$H$174,Output!C36,Dataset!$D$2:$D$174,"Laki-laki") -> 31828143 | E36: =SUMIFS(Dataset!$I$2:$I$174,Dataset!$H$2:$H$174,Output!C36,Dataset!$D$2:$D$174,"Perempuan") -> 44774317 | F36: =D36+E36 -> 76602460
C37: Maluku | D37: =SUMIFS(Dataset!$I$2:$I$174,Dataset!$H$2:$H$174,Output!C37,Dataset!$D$2:$D$174,"Laki-laki") -> 20888685 | E37: =SUMIFS(Dataset!$I$2:$I$174,Dataset!$H$2:$H$174,Output!C37,Dataset!$D$2:$D$174,"Perempuan") -> 29937365 | F37: =D37+E37 -> 50826050
C38: Total | D38: =SUM(D25:D37) -> 462722464 | E38: =SUM(E25:E37) -> 416660778 | F38: =SUM(F25:F37) -> 879383242
B40: III. Validation Phone Number
C42: Categories | D42: Total Data | E42: Ratio
C43: Valid Number | D43: =COUNTIF(Dataset!$L$2:$L$1048576,"No Asli") -> 85 | E43: =D43/$D$45 -> 0.49132948
C44: Invalid Number | D44: =COUNTIF(Dataset!$L$2:$L$1048576,"No Palsu") -> 88 | E44: =D44/$D$45 -> 0.50867052
C45: Grand Total Data | D45: =SUM(D43:D44) -> 173
B47: IV. Analysis Finding
C49: - Jawa Timur recorded the highest total funding balance at 93,870,670, while Sumatera Utara had
...
